Workbook

Sheet Cover
B3: LOCKHEED MARTIN CORPORATION
B4: NYSE: LMT | Aerospace & Defense
B6: COMPREHENSIVE FINANCIAL ANALYSIS
B7: Fiscal Years 2022 - 2024 | CFA Framework Analysis
B10: COMPANY PROFILE | G10: ANALYSIS FRAMEWORK
B11: Headquarters | D11: Bethesda, Maryland, USA | G11: Phase 1 | I11: Purpose & Context Definition
B12: Industry | D12: Aerospace & Defense | G12: Phase 2 | I12: Data Collection & Validation
B13: Employees | D13: ~122,000 | G13: Phase 3 | I13: Ratio Analysis & Processing
B14: Accounting Standard | D14: US GAAP | G14: Phase 4 | I14: Trend & Peer Comparison
B15: Fiscal Year End | D15: December 31 | G15: Phase 5 | I15: Red Flags & Quality Assessment
B16: Auditor | D16: Ernst & Young LLP | G16: Phase 6 | I16: Conclusions & Recommendations
B17: Market Cap (2024) | D17: ~$120 Billion | G17: Phase 7 | I17: Follow-Up Monitoring
B20: DATA SOURCES (APA 7th Edition)
B21: • Lockheed Martin Corporation. (2025). Form 10-K Annual Report FY2024. SEC EDGAR.
B22: • Lockheed Martin Corporation. (2024). Form 10-K Annual Report FY2023. SEC EDGAR.
B23: • Lockheed Martin Corporation. (2023). Form 10-K Annual Report FY2022. SEC EDGAR.
B24: • CFA Institute. (2020). International Financial Statement Analysis (4th ed.). Wiley.

Sheet Income Statement
B2: CONSOLIDATED INCOME STATEMENT
B3: All figures in USD Millions | Source: Form 10-K
N4: Common Size (% of Revenue)
B5: Line Item | C5: 2024 | D5: 2023 | E5: 2022 | F5: 2021 | H5: YoY % | I5: CAGR | K5: Notes | M5: 2024 | N5: 2023 | O5: 2022
B7: REVENUE
B8: Net Sales Revenue | C8: 71043 | D8: 67571 | E8: 65984 | F8: 67044 | K8: Primary revenue stream - defense contracts | M8: =(C8/C$10) -> 0.99883306 | N8: =(D8/D$10) -> 0.99958579 | O8: =(E8/E$10) -> 0.99907639
B9: Other Operating Revenue | C9: 83 | D9: 28 | E9: 61 | F9: 62 | K9: Minor; monitor for unusual spikes | M9: =(C9/C$10) -> 0.0011669432 | N9: =(D9/D$10) -> 0.00041420731 | O9: =(E9/E$10) -> 0.00092361269
B10: Total Operating Revenue | C10: =C8+C9 -> 71126 | D10: =D8+D9 -> 67599 | E10: =E8+E9 -> 66045 | F10: =F8+F9 -> 67106 | H10: =(C10-D10)/ABS(D10) -> 0.052175328 | I10: =((C10/E10)^(1/2)-1) -> 0.037753533 | K10: Key metric for growth analysis | M10: 1 | N10: 1 | O10: 1
B12: COST OF SALES
B13: Cost of Goods Sold | C13: -60954 | D13: -56162 | E13: -54593 | F13: -55119 | H13: =(C13-D13)/ABS(D13) -> -0.085324597 | I13: =((C13/E13)^(1/2)-1) -> 0.056653571 | K13: Watch: Growing faster than revenue | M13: =(-C13/C$10) -> 0.85698619 | N13: =(-D13/D$10) -> 0.83081111 | O13: =(-E13/E$10) -> 0.82660307
B15: Gross Profit | C15: =C8+C13 -> 10089 | D15: =D8+D13 -> 11409 | E15: =E8+E13 -> 11391 | F15: =F8+F13 -> 11925 | H15: =((C15-D15)/ABS(D15)) -> -0.11569813 | I15: =(C15/E15)^(1/2)-1 -> -0.058884047 | K15: Declining margin trend | M15: =(C15/C$10) -> 0.14184686 | N15: =(D15/D$10) -> 0.16877469 | O15: =(E15/E$10) -> 0.17247331
B16: Gross Margin % | C16: =C15/C8 -> 0.14201258 | D16: =D15/D8 -> 0.16884462 | E16: =E15/E8 -> 0.17263276 | F16: =F15/F8 -> 0.17786827 | K16: 300bps decline
B18: OPERATING EXPENSES
B19: R&D Costs | C19: -1600 | D19: -1500 | E19: -1700 | F19: -1500 | H19: =((C19-D19)/ABS(D19)) -> -0.066666667 | I19: =((C19/E19)^(1/2)-1) -> -0.0298575 | K19: Innovation investment; compare to peers | M19: =(-C19/C$10) -> 0.02249529 | N19: =(-D19/D$10) -> 0.022189677 | O19: =(-E19/E$10) -> 0.025740026
B20: Depreciation & Amortization | C20: -1559 | D20: -1430 | E20: -1404 | F20: -1364 | H20: =((C20-D20)/ABS(D20)) -> -0.09020979 | I20: =((C20/E20)^(1/2)-1) -> 0.053754649 | K20: Non-cash; add back for cash flow | M20: =-(C20/C$10) -> 0.021918848 | N20: =-(D20/D$10) -> 0.021154159 | O20: =-(E20/E$10) -> 0.021258233
B21: Other Operating Income/(Expense) | C21: 326 | D21: 535 | E21: -984 | F21: -942 | M21: =(C21/C$10) -> 0.0045834153 | N21: =(D21/D$10) -> 0.0079143183 | O21: =-(E21/E$10) -> 0.014898933
B22: Total Operating Expenses | C22: =SUM(C19:C21) -> -2833 | D22: =SUM(D19:D21) -> -2395 | E22: =SUM(E19:E21) -> -4088 | F22: =SUM(F19:F21) -> -3806 | M22: =-(C22/C$10) -> 0.039830723 | N22: =-(D22/D$10) -> 0.035429518 | O22: =-(E22/E$10) -> 0.061897191
B24: Operating Profit (EBIT) | C24: =C15+C22 -> 7256 | D24: =D15+D22 -> 9014 | E24: =E15+E22 -> 7303 | F24: =F15+F22 -> 8119 | H24: =((C24-D24)/ABS(D24)) -> -0.19502995 | I24: =((C24/E24)^(1/2)-1) -> -0.0032230497 | K24: Core operating performance | M24: =(C24/C$10) -> 0.10201614 | N24: =(D24/D$10) -> 0.13334517 | O24: =(E24/E$10) -> 0.11057612
B25: EBIT Margin % | C25: =C24/C10 -> 0.10201614 | D25: =D24/D10 -> 0.13334517 | E25: =E24/E10 -> 0.11057612 | F25: =F24/F10 -> 0.12098769 | K25: Key profitability metric
B27: NON-OPERATING ITEMS
B28: Interest Expense | C28: -1036 | D28: -916 | E28: -623 | F28: -569 | H28: =((C28-D28)/ABS(D28)) -> -0.13100437 | I28: =((C28/E28)^(1/2)-1) -> 0.28954308 | K28: increase in +66% - leverage concern | M28: =-(C28/C$10) -> 0.0145657 | N28: =-(D28/D$10) -> 0.013550496 | O28: =-(E28/E$10) -> 0.0094329624
B29: Other Financial Income/(Expense) | C29: 0 | D29: 0 | E29: 0 | F29: 0
B31: Earnings Before Tax (EBT) | C31: =C24+C28+C29 -> 6220 | D31: =D24+D28+D29 -> 8098 | E31: =E24+E28+E29 -> 6680 | F31: =F24+F28+F29 -> 7550 | H31: =((C31-D31)/ABS(D31)) -> -0.23190911 | I31: =((C31/E31)^(1/2)-1) -> -0.035045221 | M31: =(C31/C$10) -> 0.08745044 | N31: =(D31/D$10) -> 0.11979467 | O31: =(E31/E$10) -> 0.10114316
B32: Income Tax Expense | C32: -884 | D32: -1178 | E32: -948 | F32: -1235 | H32: =((C32-D32)/ABS(D32)) -> 0.24957555 | I32: =((C32/E32)^(1/2)-1) -> -0.034345066 | M32: =-(C32/C$10) -> 0.012428648 | N32: =-(D32/D$10) -> 0.017426293 | O32: =-(E32/E$10) -> 0.01435385
B33: Effective Tax Rate | C33: =-C32/C31 -> 0.14212219 | D33: =-D32/D31 -> 0.14546802 | E33: =-E32/E31 -> 0.14191617 | F33: =-F32/F31 -> 0.16357616
B35: Net Income | C35: =C31+C32 -> 5336 | D35: =D31+D32 -> 6920 | E35: =E31+E32 -> 5732 | F35: =F31+F32 -> 6315 | H35: =((C35-D35)/ABS(D35)) -> -0.22890173 | I35: =((C35/E35)^(1/2)-1) -> -0.035161067 | M35: =(C35/C$10) -> 0.075021792 | N35: =(D35/D$10) -> 0.10236838 | O35: =(E35/E$10) -> 0.08678931
B36: Net Margin % | C36: =C35/C10 -> 0.075021792 | D36: =D35/D10 -> 0.10236838 | E36: =E35/E10 -> 0.08678931 | F36: =F35/F10 -> 0.094104849
B40: CHART DATA
B41: Year | C41: Revenue | D41: Gross Profit | E41: EBIT | F41: Net Income
B42: 2022 | C42: =E10 -> 66045 | D42: =E15 -> 11391 | E42: =E24 -> 7303 | F42: =E35 -> 5732
B43: 2023 | C43: =D10 -> 67599 | D43: =D15 -> 11409 | E43: =D24 -> 9014 | F43: =D35 -> 6920
B44: 2024 | C44: =C10 -> 71126 | D44: =C15 -> 10089 | E44: =C24 -> 7256 | F44: =C35 -> 5336
B46: MARGIN DATA
B47: Year | C47: Gross Margin | D47: EBIT Margin | E47: Net Margin
B48: 2022 | C48: =E16 -> 0.17263276 | D48: =E25 -> 0.11057612 | E48: =E36 -> 0.08678931
B49: 2023 | C49: =D16 -> 0.16884462 | D49: =D25 -> 0.13334517 | E49: =D36 -> 0.10236838
B50: 2024 | C50: =C16 -> 0.14201258 | D50: =C25 -> 0.10201614 | E50: =C36 -> 0.075021792

Sheet Balance Sheet
B2: CONSOLIDATED BALANCE SHEET
B3: All figures in USD Millions | As of December 31
I4: Common Size (% of Total Assets)
B5: Line Item | C5: 2024 | D5: 2023 | E5: 2022 | F5: 2021 | H5: 2024 | I5: 2023 | J5: 2022
B6: ASSETS
B8: Non-Current Assets
B9: Property, Plant & Equipment | C9: 8726 | D9: 8370 | E9: 7975 | F9: 7597 | H9: =(C9/C$22) -> 0.15689447 | I9: =(D9/D$22) -> 0.1595623 | J9: =(E9/E$22) -> 0.15081316
B10: Intangible Assets & Goodwill | C10: 14982 | D10: 14411 | E10: 14158 | F10: 14296 | H10: =(C10/C$22) -> 0.26937807 | I10: =(D10/D$22) -> 0.27472548 | J10: =(E10/E$22) -> 0.26773828
B11: Long-term Financial Assets | C11: 3454 | D11: 2501 | E11: 2285 | F11: 2789 | H11: =(C11/C$22) -> 0.062103314 | I11: =(D11/D$22) -> 0.047678054 | J11: =(E11/E$22) -> 0.043211044
B12: Other Non-Current Assets | C12: 6606 | D12: 6653 | E12: 7471 | F12: 6376 | H12: =(C12/C$22) -> 0.11877663 | I12: =(D12/D$22) -> 0.12683011 | J12: =(E12/E$22) -> 0.14128215
B13: Total Non-Current Assets | C13: =SUM(C9:C12) -> 33768 | D13: =SUM(D9:D12) -> 31935 | E13: =SUM(E9:E12) -> 31889 | F13: =SUM(F9:F12) -> 31058 | H13: =(C13/C$22) -> 0.60715249 | I13: =(D13/D$22) -> 0.60879594 | J13: =(E13/E$22) -> 0.60304463 | P13: CAPITAL STRUCTURE DATA | W13: ASSET COMPOSITION DATA
P14: Year | Q14: Equity | R14: LT Debt | S14: ST Debt | T14: Other Liab | W14: Year | X14: PP&E | Y14: Intangibles | Z14: Other NCA | AA14: Current Assets
B15: Current Assets | P15: 2022 | Q15: =E46 -> 9266 | R15: =E27 -> 15429 | S15: =E34 -> 0 | T15: =E38-E27-E34 -> 28185 | W15: 2022 | X15: =E9 -> 7975 | Y15: =E10 -> 14158 | Z15: =E11+E12 -> 9756 | AA15: =E20 -> 20991
B16: Inventories | C16: 3474 | D16: 3132 | E16: 3088 | F16: 2981 | H16: =(C16/C$22) -> 0.062462916 | I16: =(D16/D$22) -> 0.059707183 | J16: =(E16/E$22) -> 0.058396369 | P16: 2023 | Q16: =D46 -> 6835 | R16: =D27 -> 17291 | S16: =D34 -> 168 | T16: =D38-D27-D34 -> 28162 | W16: 2023 | X16: =D9 -> 8370 | Y16: =D10 -> 14411 | Z16: =D11+D12 -> 9154 | AA16: =D20 -> 20521
B17: Trade Receivables | C17: 2351 | D17: 2132 | E17: 2505 | F17: 1963 | H17: =(C17/C$22) -> 0.042271248 | I17: =(D17/D$22) -> 0.040643587 | J17: =(E17/E$22) -> 0.047371407 | P17: 2024 | Q17: =C46 -> 6333 | R17: =C27 -> 19627 | S17: =C34 -> 643 | T17: =C38-C27-C34 -> 29014 | W17: 2024 | X17: =C9 -> 8726 | Y17: =C10 -> 14982 | Z17: =C11+C12 -> 10060 | AA17: =C20 -> 21849
B18: Cash & Cash Equivalents | C18: 2483 | D18: 1442 | E18: 2547 | F18: 3604 | H18: =(C18/C$22) -> 0.044644623 | I18: =(D18/D$22) -> 0.027489706 | J18: =(E18/E$22) -> 0.048165658
B19: Other Current Assets | C19: 13541 | D19: 13815 | E19: 12851 | F19: 11267 | H19: =(C19/C$22) -> 0.24346872 | I19: =(D19/D$22) -> 0.26336358 | J19: =(E19/E$22) -> 0.24302194
B20: Total Current Assets | C20: =SUM(C16:C19) -> 21849 | D20: =SUM(D16:D19) -> 20521 | E20: =SUM(E16:E19) -> 20991 | F20: =SUM(F16:F19) -> 19815 | H20: =(C20/C$22) -> 0.39284751 | I20: =(D20/D$22) -> 0.39120406 | J20: =(E20/E$22) -> 0.39695537
B22: TOTAL ASSETS | C22: =C13+C20 -> 55617 | D22: =D13+D20 -> 52456 | E22: =E13+E20 -> 52880 | F22: =F13+F20 -> 50873 | H22: 1 | I22: 1 | J22: 1
B24: LIABILITIES & EQUITY
B26: Non-Current Liabilities
B27: Long-term Debt | C27: 19627 | D27: 17291 | E27: 15429 | F27: 11670 | H27: =(C27/C$22) -> 0.3528957 | I27: =(D27/D$22) -> 0.32962864 | J27: =(E27/E$22) -> 0.29177383
B28: Provisions | C28: 5468 | D28: 6842 | E28: 6168 | F28: 9061 | H28: =(C28/C$22) -> 0.098315263 | I28: =(D28/D$22) -> 0.13043312 | J28: =(E28/E$22) -> 0.11664145
B29: Other Non-Current Liabilities | C29: 4769 | D29: 4551 | E29: 6130 | F29: 5186 | H29: =(C29/C$22) -> 0.085747164 | I29: =(D29/D$22) -> 0.086758426 | J29: =(E29/E$22) -> 0.11592284
B30: Total Non-Current Liabilities | C30: =SUM(C27:C29) -> 29864 | D30: =SUM(D27:D29) -> 28684 | E30: =SUM(E27:E29) -> 27727 | F30: =SUM(F27:F29) -> 25917 | H30: =(C30/C$22) -> 0.53695812 | I30: =(D30/D$22) -> 0.54682019 | J30: =(E30/E$22) -> 0.52433812
B32: Current Liabilities
B33: Trade Payables | C33: 2222 | D33: 2312 | E33: 2117 | F33: 780 | H33: =(C33/C$22) -> 0.039951813 | I33: =(D33/D$22) -> 0.044075034 | J33: =(E33/E$22) -> 0.040034039
B34: Short-term Debt | C34: 643 | D34: 168 | E34: 0 | F34: 6 | H34: =(C34/C$22) -> 0.011561213 | I34: =(D34/D$22) -> 0.0032026842 | J34: =(E34/E$22) -> 0
B35: Other Current Liabilities | C35: 16555 | D35: 14457 | E35: 13770 | F35: 13211 | H35: =(C35/C$22) -> 0.29766079 | I35: =(D35/D$22) -> 0.27560241 | J35: =(E35/E$22) -> 0.26040091
B36: Total Current Liabilities | C36: =SUM(C33:C35) -> 19420 | D36: =SUM(D33:D35) -> 16937 | E36: =SUM(E33:E35) -> 15887 | F36: =SUM(F33:F35) -> 13997 | H36: =(C36/C$22) -> 0.34917381 | I36: =(D36/D$22) -> 0.32288013 | J36: =(E36/E$22) -> 0.30043495
B38: TOTAL LIABILITIES | C38: =C30+C36 -> 49284 | D38: =D30+D36 -> 45621 | E38: =E30+E36 -> 43614 | F38: =F30+F36 -> 39914 | H38: =(C38/C$22) -> 0.88613194 | I38: =(D38/D$22) -> 0.86970032 | J38: =(E38/E$22) -> 0.82477307
B41: Equity
B42: Share capital | C42: 234 | D42: 240 | E42: 254 | F42: 271
B43: Other reserves | C43: -8452 | D43: -8803 | E43: -8023 | F43: -11006
A44: Other Components of Equity | B44: Other Components of Equity | C44: 0 | D44: 0 | E44: 92 | F44: 94
B45: Retained earnings | C45: 14551 | D45: 15398 | E45: 16943 | F45: 21600
B46: Total equity | C46: =SUM(C42:C45) -> 6333 | D46: =SUM(D42:D45) -> 6835 | E46: =SUM(E42:E45) -> 9266 | F46: =SUM(F42:F45) -> 10959 | H46: =(C46/C$22) -> 0.11386806 | I46: =(D46/D$22) -> 0.13029968 | J46: =(E46/E$22) -> 0.17522693
B48: TOTAL LIABILITIES & EQUITY | C48: =C38+C46 -> 55617 | D48: =D38+D46 -> 52456 | E48: =E38+E46 -> 52880 | F48: =F38+F46 -> 50873
B55: CAPITAL & ASSET STRUCTURE ANALYSIS
B56: Metric | C56: Formula | D56: 2024 | E56: 2023 | F56: 2022 | I56: Interpretation
...

Sheet Efficiency & Cash Flow
B2: OPERATING EFFICIENCY & CASH FLOW ANALYSIS
B3: All formulas linked to source sheets | CFA Framework Phase 4
B5: Metric | C5: Formula | D5: 2024 | E5: 2023 | F5: 2022 | G5: Trend | H5: Interpretation | J5: Year | K5: DIO | L5: DSO | M5: DPO | N5: CCC
B6: ASSET UTILISATION & OPERATING EFFICIENCY | J6: 2022 | K6: =F8 -> 20.64587 | L6: =F9 -> 13.84397 | M6: =F10 -> 14.153921 | N6: =F11 -> 20.33592
B7: Asset Turnover Ratio | C7: Revenue ÷ Avg Total Assets | D7: ='Income Statement'!C10/AVERAGE('Balance Sheet'!C22,'Balance Sheet'!D22) -> 1.3162585 | E7: ='Income Statement'!D10/AVERAGE('Balance Sheet'!D22,'Balance Sheet'!E22) -> 1.2834928 | F7: ='Income Statement'!E10/AVERAGE('Balance Sheet'!E22,'Balance Sheet'!F22) -> 1.2731198 | G7: → | H7: Stable ~1.28x. Efficient revenue generation per dollar of assets. | J7: 2023 | K7: =E8 -> 20.355044 | L7: =E9 -> 11.511709 | M7: =E10 -> 15.025818 | N7: =E11 -> 16.840935
B8: DIO (Days Inventory Outstanding) | C8: (Inventory ÷ |COGS|) × 365 | D8: ='Balance Sheet'!C16/'Income Statement'!C13*(-365) -> 20.802736 | E8: ='Balance Sheet'!D16/'Income Statement'!D13*(-365) -> 20.355044 | F8: ='Balance Sheet'!E16/'Income Statement'!E13*(-365) -> 20.64587 | G8: → | H8: Stable ~20 days. Fast inventory conversion due to contract-based production. | J8: 2024 | K8: =D8 -> 20.802736 | L8: =D9 -> 12.064716 | M8: =D10 -> 13.305608 | N8: =D11 -> 19.561845
B9: DSO (Days Sales Outstanding) | C9: (Receivables ÷ Revenue) × 365 | D9: ='Balance Sheet'!C17/'Income Statement'!C10*365 -> 12.064716 | E9: ='Balance Sheet'!D17/'Income Statement'!D10*365 -> 11.511709 | F9: ='Balance Sheet'!E17/'Income Statement'!E10*365 -> 13.84397 | G9: → | H9: EXCELLENT: ~12 days. Government contracts ensure rapid payment.
B10: DPO (Days Payables Outstanding) | C10: (Payables ÷ |COGS|) × 365 | D10: ='Balance Sheet'!C33/ABS('Income Statement'!C13)*365 -> 13.305608 | E10: ='Balance Sheet'!D33/ABS('Income Statement'!D13)*365 -> 15.025818 | F10: ='Balance Sheet'!E33/ABS('Income Statement'!E13)*365 -> 14.153921 | G10: ↓ | H10: Declined from 15 to 13 days. Paying suppliers faster = less leverage on credit.
B11: Cash Conversion Cycle (CCC) | C11: DIO + DSO − DPO | D11: =D8+D9-D10 -> 19.561845 | E11: =E8+E9-E10 -> 16.840935 | F11: =F8+F9-F10 -> 20.33592 | G11: ↑ | H11: CCC rising from ~17→20 days. Cash takes longer to cycle. Driven by DPO decline.
B13: CASH FLOW STATEMENT ANALYSIS
B14: Operating Cash Flow (OCF) | C14: From 10-K Cash Flow Statement | D14: 6972 | E14: 7920 | F14: 7802 | G14: ↓ | H14: CFO declining from $7,920M to $6,972M (−12%). Core cash generation weakening.
B15: Investing Cash Flow (CFI) | C15: From 10-K Cash Flow Statement | D15: -1792 | E15: -1694 | F15: -1789 | G15: → | H15: Stable investment profile. Consistent CapEx + acquisitions.
B16: Financing Cash Flow (CFF) | C16: From 10-K Cash Flow Statement | D16: -4139 | E16: -7331 | F16: -7070 | G16: ↑ | H16: Less outflow in 2024 ($4.1B vs $7.3B). Reduced share buybacks.
B17: Net Profit | C17: ='Income Statement'!CW35 -> 0 | D17: ='Income Statement'!C35 -> 5336 | E17: ='Income Statement'!D35 -> 6920 | F17: ='Income Statement'!E35 -> 5732 | G17: ↓ | H17: Net Income dropped 23% YoY ($6,920M → $5,336M).
B18: Capital Expenditure (CapEx) | C18: From 10-K Cash Flow Statement | D18: -1685 | E18: -1691 | F18: -1670 | G18: → | H18: Consistent ~$1.7B/yr. Steady maintenance + growth investment.
B19: OCF / Net Profit | C19: OCF ÷ Net Income | D19: =D14/D17 -> 1.3065967 | E19: =E14/E17 -> 1.1445087 | F19: =F14/F17 -> 1.3611305 | G19: ✓ | H19: EXCELLENT: >1.0x consistently. Cash earnings exceed accrual = HIGH quality.
B20: OCF / CapEx | C20: OCF ÷ |CapEx| | D20: =D14/ABS(D18) -> 4.1376855 | E20: =E14/ABS(E18) -> 4.6836192 | F20: =F14/ABS(F18) -> 4.6718563 | G20: ✓ | H20: STRONG: >4x means OCF easily covers reinvestment. Low capital needs.
B22: CASH FLOW QUALITY METRICS
B23: OCF / Revenue (Cash Flow Margin) | C23: OCF ÷ Revenue | D23: =D14/'Income Statement'!C10 -> 0.098023226 | E23: =E14/'Income Statement'!D10 -> 0.1171615 | F23: =F14/'Income Statement'!E10 -> 0.11813158 | G23: ↓ | H23: Declining from 11.7% to 9.8%. Less cash per dollar of revenue.
B24: FCF / Net Income (FCF Quality) | C24: (OCF − |CapEx|) ÷ Net Income | D24: =(D14-ABS(D18))/D17 -> 0.99081709 | E24: =(E14-ABS(E18))/E17 -> 0.90014451 | F24: =(F14-ABS(F18))/F17 -> 1.0697837 | G24: → | H24: ~1.0x indicates genuine earnings quality. FCF backs up reported profits.
B25: CapEx / D&A (Reinvestment Rate) | C25: |CapEx| ÷ |D&A| | D25: =ABS(D18)/ABS('Income Statement'!C20) -> 1.080821 | E25: =ABS(E18)/ABS('Income Statement'!D20) -> 1.1825175 | F25: =ABS(F18)/ABS('Income Statement'!E20) -> 1.1894587 | G25: ↓ | H25: CapEx/D&A declining. Spending less relative to depreciation. Monitor under-investment. | J25: Year | K25: OCF | L25: FCF | M25: Net Income
B26: CapEx / Revenue (Capital Intensity) | C26: |CapEx| ÷ Revenue | D26: =ABS(D18)/'Income Statement'!C10 -> 0.023690352 | E26: =ABS(E18)/'Income Statement'!D10 -> 0.025015163 | F26: =ABS(F18)/'Income Statement'!E10 -> 0.02528579 | G26: → | H26: Low ~2.4% capital intensity. Defense is asset-light relative to revenue. | J26: 2022 | K26: 7802 | L26: 6132 | M26: =F17 -> 5732
J27: 2023 | K27: 7920 | L27: 6229 | M27: =E17 -> 6920
B28: WORKING CAPITAL ANALYSIS | J28: 2024 | K28: 6972 | L28: 5287 | M28: =D17 -> 5336
B29: Current Assets | D29: ='Balance Sheet'!C20 -> 21849 | E29: ='Balance Sheet'!D20 -> 20521 | F29: ='Balance Sheet'!E20 -> 20991
B30: Current Liabilities | D30: ='Balance Sheet'!C36 -> 19420 | E30: ='Balance Sheet'!D36 -> 16937 | F30: ='Balance Sheet'!E36 -> 15887
B31: Net Working Capital (NWC) | C31: Current Assets − Current Liab | D31: =D29-D30 -> 2429 | E31: =E29-E30 -> 3584 | F31: =F29-F30 -> 5104 | G31: ↓ | H31: NWC declining but remains positive due to large 'Other CA' ($13.5B contract assets). Adjust below.
B32: NWC % of Revenue | C32: NWC ÷ Revenue | D32: =D31/'Income Statement'!C10 -> 0.034150662 | E32: =E31/'Income Statement'!D10 -> 0.053018536 | F32: =F31/'Income Statement'!E10 -> 0.077280642 | G32: ↓ | H32: NWC as % of revenue declining - working capital tightening.
B34: OPERATING WORKING CAPITAL COMPONENTS
B35: Inventories | D35: ='Balance Sheet'!C16 -> 3474 | E35: ='Balance Sheet'!D16 -> 3132 | F35: ='Balance Sheet'!E16 -> 3088
B36: Trade Receivables | D36: ='Balance Sheet'!C17 -> 2351 | E36: ='Balance Sheet'!D17 -> 2132 | F36: ='Balance Sheet'!E17 -> 2505
B37: Trade Payables | D37: ='Balance Sheet'!C33 -> 2222 | E37: ='Balance Sheet'!D33 -> 2312 | F37: ='Balance Sheet'!E33 -> 2117
B38: Operating Working Capital | C38: Inventory + Receivables − Payables | D38: =D35+D36-D37 -> 3603 | E38: =E35+E36-E37 -> 2952 | F38: =F35+F36-F37 -> 3476 | G38: ↑ | H38: Operating WC volatile ($1,262→$2,612→$3,603). Receivables & inventory absorbing more cash.

Sheet Ratio Analysis
B2: COMPREHENSIVE RATIO ANALYSIS
B3: All ratios calculated with Excel formulas referencing source data | Cell references shown
B5: Ratio | C5: Formula / Cell Reference | D5: 2024 | E5: 2023 | F5: 2022 | G5: Trend | H5: Benchmark | I5: Interpretation & CFA Notes
B6: PROFITABILITY RATIOS
B7: Gross Profit Margin | C7: Gross Profit ÷ Revenue | D7: ='Income Statement'!C15/'Income Statement'!C8 -> 0.14201258 | E7: ='Income Statement'!D15/'Income Statement'!D8 -> 0.16884462 | F7: ='Income Statement'!E15/'Income Statement'!E8 -> 0.17263276 | G7: ↓ | H7: 15-20% | I7: 300bps decline indicates cost pressure or pricing erosion
B8: Operating Margin (EBIT) | C8: EBIT ÷ Revenue | D8: ='Income Statement'!C24/'Income Statement'!C8 -> 0.10213533 | E8: ='Income Statement'!D24/'Income Statement'!D8 -> 0.13340042 | F8: ='Income Statement'!E24/'Income Statement'!E8 -> 0.11067835 | G8: ↓ | H8: 10-12% | I8: Core operating efficiency declining
B9: Net Profit Margin | C9: Net Income ÷ Revenue | D9: ='Income Statement'!C35/'Income Statement'!C8 -> 0.075109441 | E9: ='Income Statement'!D35/'Income Statement'!D8 -> 0.1024108 | F9: ='Income Statement'!E35/'Income Statement'!E8 -> 0.086869544 | G9: ↓ | H9: 8-10% | I9: Bottom line profitability
B10: Return on Equity (ROE) | C10: Net Income ÷ Avg Equity | D10: ='Income Statement'!C35/AVERAGE('Balance Sheet'!C46:D46) -> 0.81044957 | E10: ='Income Statement'!D35/AVERAGE('Balance Sheet'!D46:E46) -> 0.85957394 | F10: ='Income Statement'!E35/AVERAGE('Balance Sheet'!E46:F46) -> 0.56682324 | G10: ↑ | H10: 15-25% | I10: HIGH due to leverage - see DuPont
B11: Return on Assets (ROA) | C11: Net Income ÷ Avg Assets | D11: ='Income Statement'!C35/AVERAGE('Balance Sheet'!C22:D22) -> 0.098748068 | E11: ='Income Statement'!D35/AVERAGE('Balance Sheet'!D22:E22) -> 0.13138908 | F11: ='Income Statement'!E35/AVERAGE('Balance Sheet'!E22:F22) -> 0.11049319 | G11: ↓ | H11: 8-12% | I11: True operational return - declining
B12: Basic Earning Power (BEP) | C12: EBIT ÷ Total Assets | D12: ='Income Statement'!C24/'Balance Sheet'!C22 -> 0.13046371 | E12: ='Income Statement'!D24/'Balance Sheet'!D22 -> 0.17183926 | F12: ='Income Statement'!E24/'Balance Sheet'!E22 -> 0.13810514 | G12: ↓
B14: LIQUIDITY RATIOS
B15: Current Ratio | C15: Current Assets ÷ Current Liab | D15: ='Balance Sheet'!C20/'Balance Sheet'!C36 -> 1.1250772 | E15: ='Balance Sheet'!D20/'Balance Sheet'!D36 -> 1.2116077 | F15: ='Balance Sheet'!E20/'Balance Sheet'!E36 -> 1.321269 | G15: ↓ | H15: 1.5-2.0x | I15: Below benchmark - liquidity tightening
B16: Quick Ratio | C16: (CA - Inventory) ÷ CL | D16: =('Balance Sheet'!C20-'Balance Sheet'!C16)/'Balance Sheet'!C36 -> 0.9461895 | E16: =('Balance Sheet'!D20-'Balance Sheet'!D16)/'Balance Sheet'!D36 -> 1.0266871 | F16: =('Balance Sheet'!E20-'Balance Sheet'!E16)/'Balance Sheet'!E36 -> 1.1268962 | G16: ↓ | H16: >1.0x | I16: Below 1.0 - immediate liquidity concern
B17: Cash Ratio | C17: Cash ÷ Current Liabilities | D17: ='Balance Sheet'!C18/'Balance Sheet'!C36 -> 0.12785788 | E17: ='Balance Sheet'!D18/'Balance Sheet'!D36 -> 0.085139045 | F17: ='Balance Sheet'!E18/'Balance Sheet'!E36 -> 0.16031976 | G17: ↑ | H17: >0.2x | I17: Minimal cash buffer
B19: SOLVENCY RATIOS
B20: Debt-to-Equity | C20: Total Debt ÷ Equity | D20: =('Balance Sheet'!C27+'Balance Sheet'!C34)/'Balance Sheet'!C46 -> 3.2006948 | E20: =('Balance Sheet'!D27+'Balance Sheet'!D34)/'Balance Sheet'!D46 -> 2.5543526 | F20: =('Balance Sheet'!E27+'Balance Sheet'!E34)/'Balance Sheet'!E46 -> 1.6651198 | G20: ↑ | H20: 0.5-1.5x | I20: CRITICAL: Far exceeds industry norm
B21: Debt-to-Assets | C21: Total Debt ÷ Total Assets | D21: =('Balance Sheet'!C27+'Balance Sheet'!C34)/'Balance Sheet'!C22 -> 0.36445691 | E21: =('Balance Sheet'!D27+'Balance Sheet'!D34)/'Balance Sheet'!D22 -> 0.33283133 | F21: =('Balance Sheet'!E27+'Balance Sheet'!E34)/'Balance Sheet'!E22 -> 0.29177383 | G21: ↑ | H21: <40% | I21: Increasing debt burden
B22: Interest Coverage | C22: EBIT ÷ Interest Expense | D22: ='Income Statement'!C24/ABS('Income Statement'!C28) -> 7.003861 | E22: ='Income Statement'!D24/ABS('Income Statement'!D28) -> 9.8406114 | F22: ='Income Statement'!E24/ABS('Income Statement'!E28) -> 11.722311 | G22: ↓ | H22: >5.0x | I22: Declining but still adequate
B23: Financial Leverage | C23: Avg Assets ÷ Avg Equity | D23: =(('Balance Sheet'!C22+'Balance Sheet'!D22)/2)/(('Balance Sheet'!C46+'Balance Sheet'!D46)/2) -> 8.2072448 | E23: =(('Balance Sheet'!D22+'Balance Sheet'!E22)/2)/(('Balance Sheet'!D46+'Balance Sheet'!E46)/2) -> 6.5422023 | F23: ='Balance Sheet'!E22/'Balance Sheet'!E46 -> 5.7068854 | G23: ↑ | H23: 2-4x | I23: Very high - drives ROE
B25: EFFICIENCY RATIOS
B26: Asset Turnover | C26: Revenue ÷ Avg Assets | D26: ='Income Statement'!C10/(('Balance Sheet'!C22+'Balance Sheet'!D22)/2) -> 1.3162585 | E26: ='Income Statement'!D10/(('Balance Sheet'!D22+'Balance Sheet'!E22)/2) -> 1.2834928 | F26: ='Income Statement'!E10/'Balance Sheet'!E22 -> 1.2489599 | G26: → | H26: 1.0-1.5x | I26: Stable asset utilization
B27: Receivables Turnover | C27: Revenue ÷ Avg Receivables | D27: ='Income Statement'!C10/(('Balance Sheet'!C17+'Balance Sheet'!D17)/2) -> 31.73143 | E27: ='Income Statement'!D10/(('Balance Sheet'!D17+'Balance Sheet'!E17)/2) -> 29.156351 | F27: ='Income Statement'!E10/'Balance Sheet'!E17 -> 26.365269 | G27: ↑ | H27: >10x | I27: Excellent collection efficiency
B28: Days Sales Outstanding | C28: 365 ÷ Receivables Turnover | D28: =365/D27 -> 11.502791 | E28: =365/E27 -> 12.518713 | F28: =365/F27 -> 13.84397 | G28: ↓ | H28: <30 days | I28: Fast collection period
B29: Inventory Turnover | C29: COGS ÷ Avg Inventory | D29: =ABS('Income Statement'!C13)/(('Balance Sheet'!C16+'Balance Sheet'!D16)/2) -> 18.454133 | E29: =ABS('Income Statement'!D13)/(('Balance Sheet'!D16+'Balance Sheet'!E16)/2) -> 18.058521 | F29: =ABS('Income Statement'!E13)/'Balance Sheet'!E16 -> 17.67908 | G29: ↑ | H29: >10x | I29: Strong inventory management
B30: Days Inventory | C30: 365 ÷ Inventory Turnover | D30: =365/D29 -> 19.778768 | E30: =365/E29 -> 20.212065 | F30: =365/F29 -> 20.64587 | G30: ↓ | H30: <30 days | I30: Quick inventory cycle

Sheet DuPont Analysis
B2: DUPONT DECOMPOSITION ANALYSIS
B3: Understanding the drivers of Return on Equity
B5: 3-FACTOR DUPONT MODEL: ROE = NPM × Asset Turnover × Financial Leverage
B7: Component | C7: Formula | D7: 2024 | E7: 2023 | F7: 2022 | G7: Interpretation
B8: Net Profit Margin | C8: Net Income ÷ Revenue | D8: ='Income Statement'!C35/'Income Statement'!C10 -> 0.075021792 | E8: ='Income Statement'!D35/'Income Statement'!D10 -> 0.10236838 | F8: ='Income Statement'!E35/'Income Statement'!E10 -> 0.08678931 | G8: DECLINING - margin compression
B9: Asset Turnover | C9: Revenue ÷ Avg Assets | D9: ='Income Statement'!C10/(('Balance Sheet'!C22+'Balance Sheet'!D22)/2) -> 1.3162585 | E9: ='Income Statement'!D10/(('Balance Sheet'!D22+'Balance Sheet'!E22)/2) -> 1.2834928 | F9: ='Income Statement'!E10/'Balance Sheet'!E22 -> 1.2489599 | G9: STABLE - efficient asset use
B10: Financial Leverage | C10: Avg Assets ÷ Avg Equity | D10: =(('Balance Sheet'!C22+'Balance Sheet'!D22)/2)/(('Balance Sheet'!C46+'Balance Sheet'!D46)/2) -> 8.2072448 | E10: =(('Balance Sheet'!D22+'Balance Sheet'!E22)/2)/(('Balance Sheet'!D46+'Balance Sheet'!E46)/2) -> 6.5422023 | F10: ='Balance Sheet'!E22/'Balance Sheet'!E46 -> 5.7068854 | G10: INCREASING - drives ROE
B11: ROE (Calculated) | C11: NPM × AT × FL | D11: =D8*D9*D10 -> 0.81044957 | E11: =E8*E9*E10 -> 0.85957394 | F11: =F8*F9*F10 -> 0.61860566
B12: ROE (Direct) | C12: Net Income ÷ Avg Equity | D12: ='Income Statement'!C35/(('Balance Sheet'!C46+'Balance Sheet'!D46)/2) -> 0.81044957 | E12: ='Income Statement'!D35/(('Balance Sheet'!D46+'Balance Sheet'!E46)/2) -> 0.85957394 | F12: ='Income Statement'!E35/'Balance Sheet'!E46 -> 0.61860566
B15: KEY INSIGHT: THE ROE ILLUSION
B16: Lockheed Martin's ROE appears exceptionally high (~80%+), but DuPont analysis reveals the truth: • Net Profit Margin is DECLINING (8.7% → 7.5%) - operational weakness • Asset Turnover is STABLE (~1.28x) - no efficiency improvement • Financial Leverage is DRAMATICALLY INCREASING (5.7x → 8.8x) - the ONLY driver of high ROE

Sheet Red Flags Analysis
B2: CFA RED FLAGS ANALYSIS
B3: Earnings Quality Assessment per CFA Institute Framework
B5: Red Flag Indicator | C5: Metric | D5: 2024 | E5: 2023 | F5: 2022 | G5: Status | H5: Notes
B6: 1. Receivables vs Revenue | C6: Revenue Growth | D6: =('Income Statement'!C10-'Income Statement'!D10)/'Income Statement'!D10 -> 0.052175328 | E6: =('Income Statement'!D10-'Income Statement'!E10)/'Income Statement'!E10 -> 0.023529412
C7: Receivables Growth | D7: =('Balance Sheet'!C17-'Balance Sheet'!D17)/'Balance Sheet'!D17 -> 0.10272045 | E7: =('Balance Sheet'!D17-'Balance Sheet'!E17)/'Balance Sheet'!E17 -> -0.1489022
C8: Assessment | H8: Receivables grew slower than revenue
B10: 2. Margin Volatility | C10: Gross Margin Δ | D10: ='Ratio Analysis'!D7-'Ratio Analysis'!F7 -> -0.030620176
C11: Assessment | H11: 300bps decline
B13: 3. One-Off Items | C13: Other Operating Inc/Exp | D13: ='Income Statement'!C21 -> 326 | E13: ='Income Statement'!D21 -> 535 | F13: ='Income Statement'!E21 -> -984
C14: Assessment | H14: Volatile swings (+326 to -984) - normalize for valuation
B16: 4. Interest Expense Trend | C16: Interest Expense Growth | D16: =('Income Statement'!C28-'Income Statement'!D28)/ABS('Income Statement'!D28) -> -0.13100437 | E16: =('Income Statement'!D28-'Income Statement'!E28)/ABS('Income Statement'!E28) -> -0.47030498
C17: Assessment | H17: +13% YoY increase signals rising debt burden
B19: 5. Cash vs Accrual | C19: Net Income | D19: ='Income Statement'!C35 -> 5336 | E19: ='Income Statement'!D35 -> 6920 | F19: ='Income Statement'!E35 -> 5732
C20: OCF (estimate) | D20: 6972 | E20: 7920 | F20: 7802
C21: OCF/NI Ratio | D21: =IFERROR(D20/D19,"-") -> 1.3065967 | E21: =IFERROR(E20/E19,"-") -> 1.1445087 | F21: =IFERROR(F20/F19,"-") -> 1.3611305
C22: Assessment | H22: STRONG: OCF > NI indicates high earnings quality
B25: OVERALL EARNINGS QUALITY ASSESSMENT
B26: Summary: Lockheed Martin shows MIXED earnings quality signals: POSITIVES: Strong cash conversion (OCF > Net Income), efficient receivables collection, no channel stuffing evident CONCERNS: Significant margin compression without clear explanation, rising leverage and interest costs, volatile other operating items RECOMMENDATION: Normalize earnings by removing one-offs before valuation. Focus on operating cash flow trends. Monitor margin recovery closely.

Sheet Peer Comparison
B2: INDUSTRY PEER COMPARISON
B3: FY 2024 | Major Defense Contractors
B5: Metric | C5: LMT | D5: RTX | E5: NOC | F5: GD | G5: Industry Avg | H5: LMT Rank | I5: Assessment
B6: Revenue ($B) | C6: 71.1 | D6: 80.7 | E6: 41 | F6: 47.7 | G6: =AVERAGE(C6:F6) -> 60.125 | H6: #2 | I6: Largest pure-defense contractor
B7: Revenue Growth | C7: 0.052 | D7: 0.172 | E7: 0.044 | F7: 0.129 | G7: =AVERAGE(C7:F7) -> 0.09925 | H7: #4 | I7: Slowest growth among peers
B8: Gross Margin | C8: 0.142 | D8: 0.191 | E8: 0.18 | F8: 0.1 | G8: =AVERAGE(C8:F8) -> 0.15325 | H8: #3 | I8: Below RTX and NOC
B9: Operating Margin | C9: 0.102 | D9: 0.081 | E9: 0.107 | F9: 0.097 | G9: =AVERAGE(C9:F9) -> 0.09675 | H9: #2 | I9: Competitive
B10: Net Margin | C10: 0.075 | D10: 0.059 | E10: 0.1 | F10: 0.079 | G10: =AVERAGE(C10:F10) -> 0.07825 | H10: #3 | I10: Middle of pack
B11: ROE | C11: 0.81 | D11: 0.08 | E11: 0.273 | F11: 0.25 | G11: =AVERAGE(C11:F11) -> 0.35325 | H11: #1 | I11: Misleading - leverage driven
B12: ROA | C12: 0.096 | D12: 0.03 | E12: 0.085 | F12: 0.08 | G12: =AVERAGE(C12:F12) -> 0.07275 | H12: #1 | I12: True operational return
B13: Debt/Equity | C13: 3.2 | D13: 0.7 | E13: 1.1 | F13: 0.8 | G13: =AVERAGE(C13:F13) -> 1.45 | H13: #4 | I13: HIGHEST leverage - risk
B14: Current Ratio | C14: 1.13 | D14: 1.05 | E14: 1.2 | F14: 1.15 | G14: =AVERAGE(C14:F14) -> 1.1325 | H14: #3 | I14: Below benchmark
B15: Interest Coverage | C15: 7 | D15: 4.2 | E15: 8.5 | F15: 12 | G15: =AVERAGE(C15:F15) -> 7.925 | H15: #3 | I15: Adequate but declining
B18: COMPETITIVE POSITION SUMMARY
B20: STRENGTHS | C20: • Largest pure-defense contractor • Highest ROA among peers • Strong backlog ($176B) • F-35 program dominance | F20: WEAKNESSES | G20: • Highest leverage (D/E 3.2x) • Lowest gross margin • Slowest revenue growth • ONLY peer with margin decline

Sheet IFRS vs GAAP
B2: IFRS vs US GAAP — DEFENSE INDUSTRY COMPARISON
B3: Lockheed Martin (US GAAP) vs BAE Systems (IFRS) | Requirement 3 Advanced + FX Impact
B5: ACCOUNTING FRAMEWORK DIFFERENCES
B6: Topic | C6: US GAAP (LMT) | D6: IFRS (BAE Systems) | E6: Impact on Comparability
B7: Revenue Recognition | C7: ASC 606 — % completion for long-term defense contracts; point-in-time for standard deliveries | D7: IFRS 15 — Same principle but IFRS allows more judgment in identifying performance obligations | E7: Minimal difference post-convergence. Both use input/output methods for defense contracts.
B8: R&D Costs | C8: ALL R&D expensed as incurred (ASC 730). LMT: $1.6B expensed in 2024 | D8: Research expensed; Development costs CAPITALIZED if 6 criteria met (IAS 38) | E8: BAE may capitalize development → higher assets & profits. Adjust for comparison.
B9: Inventory Valuation | C9: LIFO permitted. Lower of cost or market | D9: LIFO PROHIBITED (IAS 2). Must use FIFO or weighted average. Lower of cost or NRV | E9: LIFO creates lower reported inventory & profits in inflation. Major comparability issue.
B10: Leases | C10: ASC 842 — Operating vs Finance distinction; both on BS | D10: IFRS 16 — Single model; virtually ALL leases on BS | E10: IFRS 16 creates larger ROU assets and lease liabilities. Adjust D/E.
B11: Goodwill | C11: Not amortized; annual impairment (ASC 350). LMT: $10.8B | D11: Not amortized; annual impairment (IAS 36) | E11: Similar treatment. Minor differences in impairment methodology.
B12: Pension Obligations | C12: Corridor approach; remeasurements in OCI (ASC 715) | D12: Immediate OCI recognition (IAS 19R). No corridor smoothing | E12: GAAP corridor smooths volatility. IFRS shows full impact immediately.
B13: Government Grants | C13: No specific standard; reduce cost or income (ASC 740 for tax) | D13: IAS 20 — Reduce asset cost or deferred income | E13: Defense firms get significant grants. Different presentation affects margins.
B14: Foreign Currency | C14: ASC 830 — Functional currency approach; FX in OCI | D14: IAS 21 — Similar functional currency; FX in OCI | E14: BAE in GBP. LMT ~27% intl revenue = FX exposure.
B17: FINANCIAL METRICS COMPARISON (FY 2024)
B18: Metric | C18: LMT (US GAAP) | D18: BAE Systems (IFRS) | E18: Commentary
B19: Revenue | C19: $71.1B | D19: £28.3B (~$36B) | E19: LMT ~2x larger. BAE growing faster (14% vs 5.2%)
B20: Gross Margin | C20: 14.2% | D20: ~21% | E20: BAE higher — partly IFRS dev cost capitalization
B21: Net Margin | C21: 7.5% | D21: ~8.5% | E21: BAE slightly better; adjust for accounting diffs
B22: D/E Ratio | C22: 3.20x | D22: ~0.90x | E22: LMT far more leveraged from buybacks
B23: R&D Treatment | C23: Fully expensed ($1.6B) | D23: Partially capitalized | E23: If LMT capitalized R&D, margins appear higher
B24: Revenue Growth | C24: 5.2% | D24: ~14% | E24: BAE benefits from European defense spending surge
B25: Inventory Method | C25: LIFO available | D25: FIFO/Weighted Avg only | E25: LIFO reserve adjustment needed for comparison
B26: Pension Provisions | C26: $5.5B (smoothed) | D26: Immediate OCI | E26: Different volatility profiles in equity
B29: FOREIGN EXCHANGE & INTERNATIONAL OPERATIONS
B30: Factor | C30: Detail | D30: Context | E30: Comparability Impact
B31: LMT International Revenue | C31: ~$19.2B (27% of total) | D31: F-35 program is largest source: 9 partner nations + FMS customers | E31: USD-denominated contracts reduce direct FX translation risk
B32: Currency Exposure | C32: USD (primary), EUR, GBP, JPY, AUD | D32: Supply chain costs in foreign currencies create transaction exposure | E32: LMT uses FX forwards & options to hedge (10-K Note 12)
B33: USD Strength Impact | C33: Favorable for LMT cost structure | D33: Strong USD = cheaper imported components and sub-assemblies | E33: Unfavorable for BAE when translating USD revenue to GBP
B34: BAE Currency Profile | C34: ~40% revenue in USD (from BAE Inc.) | D34: Remaining in GBP, EUR, SAR (Saudi Arabia) | E34: Multi-currency exposure requires aggressive hedging
B35: Analyst Adjustment | C35: P&L: Average FX rate | D35: Balance Sheet: Closing rate | E35: Note: BAE's USD revenue creates natural hedge vs USD costs
B38: KEY COMPARABILITY CONCLUSION
B39: REQUIRED ADJUSTMENTS for LMT vs BAE comparison:
B40: 1. R&D: Add back BAE's capitalized development costs to expenses for like-for-like margin comparison
B41: 2. Inventory: Adjust LMT LIFO reserve for FIFO equivalence (disclosed in 10-K inventory footnote)
B42: 3. Currency: Convert BAE financials at average rate (P&L) and closing rate (BS) consistently
B43: 4. Pension: Note different volatility profiles — GAAP corridor smoothing vs IFRS immediate recognition
B44: 5. Leases: IFRS 16 capitalizes more leases — adjust BAE's D/E for comparability with LMT's ASC 842 split
B45: BOTTOM LINE: After adjustments, LMT's operating gap with BAE narrows, but leverage (D/E 3.2x vs 0.9x) remains the primary risk.
